============================= test session starts ==============================
platform linux -- Python 3.8.10, pytest-5.4.2, py-1.8.1, pluggy-0.13.1 -- /home/arthur/ts_venv/bin/python3
cachedir: .pytest_cache
rootdir: /home/arthur/projects/qx_sw/tests, inifile: pytest.ini
plugins: timeout-1.4.2, timestamper-0.0.9
collecting ... collected 0 items / 1 error

==================================== ERRORS ====================================
________ ERROR collecting AncillaryInspectorTests/test_anc_location.py _________
../../../../ts_venv/lib/python3.8/site-packages/pluggy/hooks.py:286: in __call__
    return self._hookexec(self, self.get_hookimpls(), kwargs)
../../../../ts_venv/lib/python3.8/site-packages/pluggy/manager.py:93: in _hookexec
    return self._inner_hookexec(hook, methods, kwargs)
../../../../ts_venv/lib/python3.8/site-packages/pluggy/manager.py:84: in <lambda>
    self._inner_hookexec = lambda hook, methods, kwargs: hook.multicall(
../../../../ts_venv/lib/python3.8/site-packages/_pytest/python.py:246: in pytest_pycollect_makeitem
    res = list(collector._genfunctions(name, obj))
../../../../ts_venv/lib/python3.8/site-packages/_pytest/python.py:413: in _genfunctions
    self.ihook.pytest_generate_tests.call_extra(methods, dict(metafunc=metafunc))
../../../../ts_venv/lib/python3.8/site-packages/pluggy/hooks.py:324: in call_extra
    return self(**kwargs)
../../../../ts_venv/lib/python3.8/site-packages/pluggy/hooks.py:286: in __call__
    return self._hookexec(self, self.get_hookimpls(), kwargs)
../../../../ts_venv/lib/python3.8/site-packages/pluggy/manager.py:93: in _hookexec
    return self._inner_hookexec(hook, methods, kwargs)
../../../../ts_venv/lib/python3.8/site-packages/pluggy/manager.py:84: in <lambda>
    self._inner_hookexec = lambda hook, methods, kwargs: hook.multicall(
../conftest.py:114: in pytest_generate_tests
    unit = make_qx(hostname=qx_generator)
../../../../ts_venv/lib/python3.8/site-packages/test_system/factory.py:16: in make_qx
    qx = Qx(*args, **kwargs)
../../../../ts_venv/lib/python3.8/site-packages/test_system/models/qxseries/qx.py:158: in __init__
    raise QxException(f"Failed to obtain an IP address for Hostname: {self.hostname}")
E   test_system.models.qxseries.qxexception.QxException: Failed to obtain an IP address for Hostname: test_anc_location.py
- generated xml file: /home/arthur/projects/qx_sw/tests/AncillaryInspectorTests/.junit.xml -
=========================== short test summary info ============================
ERROR test_anc_location.py - test_system.models.qxseries.qxexception.QxExcept...
!!!!!!!!!!!!!!!!!!!! Interrupted: 1 error during collection !!!!!!!!!!!!!!!!!!!!
============================== 1 error in 15.39s ===============================
